<?xml version="1.0" ?>
<sdf version="1.6">
  <world name="car_world">
    <include>
      <uri>model://ground_plane</uri>
    </include>
    <model name="car">
      <pose>0 0 0 0 0 0</pose>
      <static>false</static>
      <link name="base_link">
        <visual name="visual">
          <geometry>
            <box>
              <size>2 1 0.5</size>
            </box>
          </geometry>
          <material>
            <script>
              <uri>file://media/materials/scripts/gazebo.material</uri>
              <name>Gazebo/Blue</name>
            </script>
          </material>
        </visual>
        <collision name="collision">
          <geometry>
            <box>
              <size>2 1 0.5</size>
            </box>
          </geometry>
        </collision>
      </link>
      
      <!-- Add a joint for the wheel -->
      <joint name="wheel_joint" type="continuous">
        <parent>base_link</parent>
        <child>wheel_link</child>
        <axis>
          <xyz>0 0 1</xyz>
        </axis>
      </joint>
      
      <link name="wheel_link">
        <pose>1 0 0 0 0 0</pose>
        <collision name="wheel_collision">
          <geometry>
            <cylinder>
              <radius>0.25</radius>
              <length>0.1</length>
            </cylinder>
          </geometry>
        </collision>
        <visual name="wheel_visual">
          <geometry>
            <cylinder>
              <radius>0.25</radius>
              <length>0.1</length>
            </cylinder>
          </geometry>
          <material>
            <script>
              <uri>file://media/materials/scripts/gazebo.material</uri>
              <name>Gazebo/Black</name>
            </script>
          </material>
        </visual>
      </link>
    </model>
  </world>
</sdf>
